
        Message type:   ERROR
        Location:       /home/jelian/myflask/blog_env/local/lib/python2.7/site-packages/flask/app.py: 1587
        Module:         app
        Function:       log_exception
        Time:           2016-08-18 21:45:20,109

        Message:

            Exception on /login [GET]
    
Traceback (most recent call last):
  File "/home/jelian/myflask/blog_env/local/lib/python2.7/site-packages/flask/app.py", line 1988, in wsgi_app
    response = self.full_dispatch_request()
  File "/home/jelian/myflask/blog_env/local/lib/python2.7/site-packages/flask/app.py", line 1641, in full_dispatch_request
    rv = self.handle_user_exception(e)
  File "/home/jelian/myflask/blog_env/local/lib/python2.7/site-packages/flask/app.py", line 1544, in handle_user_exception
    reraise(exc_type, exc_value, tb)
  File "/home/jelian/myflask/blog_env/local/lib/python2.7/site-packages/flask/app.py", line 1639, in full_dispatch_request
    rv = self.dispatch_request()
  File "/home/jelian/myflask/blog_env/local/lib/python2.7/site-packages/flask/app.py", line 1625, in dispatch_request
    return self.view_functions[rule.endpoint](**req.view_args)
  File "flask_blog.py", line 69, in login
    return render_template('login.html', error=errors)
NameError: global name 'errors' is not defined
